Workbook

Sheet CONTROL
B2: CAMPEONATO DE MARCAS | D2: 3ER MEETING 2026 | F2: PARTICIPACIÓN | H2: 1000 | J2: ACUMULADO ANTERIOR | M2: 15999 | P2: INSCRIPCION | R2: 3000 | S2: SEMANAS | T2: 8 | U2: MEETING ANTERIOR | V2: 20 | X2: SEMANAS ACUMULADAS ANTERIOR
A3: 00 | B3: CODIGO | C3: NOMBRE PARTICIPANTE | D3: PAGO INSCRIPCION | E3: 06/09/2026 | F3: 13/09/2026 | G3: 20/09/2026 | H3: 27/09/2026 | I3: 04/10/2026 | J3: 11/10/2026 | K3: 18/10/2026 | L3: 25/10/2026 | M3: Columna1 | N3: Columna2 | O3: Columna3 | P3: Columna4 | Q3: Columna5 | R3: SEMANAS PARTICIPADAS | S3: APORTADO ACUMULADO DEL MEETING | T3: APORTADO ACUMULADO TOTAL ACIERTOS | U3: ACUMULADO A COBRAR TOTAL ACIERTOS | V3: ACUMULADO ANTERIOR | X3: 4
A4: =A3+1 -> 1 | B4: COD 01 | C4: GANADORES Y PULSO | D4: 3000 | E4: X | F4: X | G4: X | R4: =COUNTIF(E4:Q4,"X") -> 3 | S4: =(($H$2-($H$2*0.2))/3)*CONTROL!$R4 -> 800 | T4: =((CONTROL!$R4*$H$2)*26.66666%)+IF(V4="SI",$M$2/$V$2,0) -> 1599.9498 | U4: =SUMIFS(E$56:Q$56,E4:Q4,"X")+IF(V4="SI",$M$2,0) -> 38665.661 | V4: SI
A5: =A4+1 -> 2 | B5: COD 02 | C5: JESUS QUERALES | D5: 3000 | E5: X | F5: X | R5: =COUNTIF(E5:Q5,"X") -> 2 | S5: =(($H$2-($H$2*0.2))/3)*CONTROL!$R5 -> 533.33333 | T5: =((CONTROL!$R5*$H$2)*26.66666%)+IF(V5="SI",$M$2/$V$2,0) -> 1333.2832 | U5: =SUMIFS(E$56:Q$56,E5:Q5,"X")+IF(V5="SI",$M$2,0) -> 35198.995 | V5: SI
A6: =A5+1 -> 3 | B6: COD 03 | C6: MUÑECA DEL HIPISMO | D6: 3000 | E6: X | F6: X | G6: X | R6: =COUNTIF(E6:Q6,"X") -> 3 | S6: =(($H$2-($H$2*0.2))/3)*CONTROL!$R6 -> 800 | T6: =((CONTROL!$R6*$H$2)*26.66666%)+IF(V6="SI",$M$2/$V$2,0) -> 1599.9498 | U6: =SUMIFS(E$56:Q$56,E6:Q6,"X")+IF(V6="SI",$M$2,0) -> 38665.661 | V6: SI
A7: =A6+1 -> 4 | B7: COD 04 | C7: EL HIPICO 701 | D7: 3000 | E7: X | F7: X | G7: X | H7: O | I7: O | R7: =COUNTIF(E7:Q7,"X") -> 3 | S7: =(($H$2-($H$2*0.2))/3)*CONTROL!$R7 -> 800 | T7: =((CONTROL!$R7*$H$2)*26.66666%)+IF(V7="SI",$M$2/$V$2,0) -> 1599.9498 | U7: =SUMIFS(E$56:Q$56,E7:Q7,"X")+IF(V7="SI",$M$2,0) -> 38665.661 | V7: SI
A8: =A7+1 -> 5 | B8: COD 05 | C8: MARCOS HIDALGO | D8: 3000 | E8: X | F8: X | R8: =COUNTIF(E8:Q8,"X") -> 2 | S8: =(($H$2-($H$2*0.2))/3)*CONTROL!$R8 -> 533.33333 | T8: =((CONTROL!$R8*$H$2)*26.66666%)+IF(V8="SI",$M$2/$V$2,0) -> 1333.2832 | U8: =SUMIFS(E$56:Q$56,E8:Q8,"X")+IF(V8="SI",$M$2,0) -> 35198.995 | V8: SI
A9: =A8+1 -> 6 | B9: COD 06 | C9: JESUS ROJAS | D9: 3000 | E9: X | F9: X | G9: X | H9: O | I9: O | J9: O | K9: O | L9: O | R9: =COUNTIF(E9:Q9,"X") -> 3 | S9: =(($H$2-($H$2*0.2))/3)*CONTROL!$R9 -> 800 | T9: =((CONTROL!$R9*$H$2)*26.66666%)+IF(V9="SI",$M$2/$V$2,0) -> 799.9998 | U9: =SUMIFS(E$56:Q$56,E9:Q9,"X")+IF(V9="SI",$M$2,0) -> 22666.661 | V9: NO
A10: =A9+1 -> 7 | B10: COD 07 | C10: NELSON OSORIO | D10: 3000 | E10: X | F10: X | G10: X | R10: =COUNTIF(E10:Q10,"X") -> 3 | S10: =(($H$2-($H$2*0.2))/3)*CONTROL!$R10 -> 800 | T10: =((CONTROL!$R10*$H$2)*26.66666%)+IF(V10="SI",$M$2/$V$2,0) -> 1599.9498 | U10: =SUMIFS(E$56:Q$56,E10:Q10,"X")+IF(V10="SI",$M$2,0) -> 38665.661 | V10: SI
A11: =A10+1 -> 8 | B11: COD 08 | C11: RUBEN DARIO CARDENAS | D11: 3000 | E11: X | F11: X | R11: =COUNTIF(E11:Q11,"X") -> 2 | S11: =(($H$2-($H$2*0.2))/3)*CONTROL!$R11 -> 533.33333 | T11: =((CONTROL!$R11*$H$2)*26.66666%)+IF(V11="SI",$M$2/$V$2,0) -> 1333.2832 | U11: =SUMIFS(E$56:Q$56,E11:Q11,"X")+IF(V11="SI",$M$2,0) -> 35198.995 | V11: SI
A12: =A11+1 -> 9 | B12: COD 09 | C12: JESUS ARASME | D12: 3000 | E12: X | F12: X | R12: =COUNTIF(E12:Q12,"X") -> 2 | S12: =(($H$2-($H$2*0.2))/3)*CONTROL!$R12 -> 533.33333 | T12: =((CONTROL!$R12*$H$2)*26.66666%)+IF(V12="SI",$M$2/$V$2,0) -> 1333.2832 | U12: =SUMIFS(E$56:Q$56,E12:Q12,"X")+IF(V12="SI",$M$2,0) -> 35198.995 | V12: SI
A13: =A12+1 -> 10 | B13: COD 10 | C13: JESUS CARAYACA | D13: 3000 | E13: X | F13: X | G13: X | R13: =COUNTIF(E13:Q13,"X") -> 3 | S13: =(($H$2-($H$2*0.2))/3)*CONTROL!$R13 -> 800 | T13: =((CONTROL!$R13*$H$2)*26.66666%)+IF(V13="SI",$M$2/$V$2,0) -> 1599.9498 | U13: =SUMIFS(E$56:Q$56,E13:Q13,"X")+IF(V13="SI",$M$2,0) -> 38665.661 | V13: SI
A14: =A13+1 -> 11 | B14: COD 11 | C14: ANDERSON ZERPA | D14: 3000 | E14: X | F14: X | R14: =COUNTIF(E14:Q14,"X") -> 2 | S14: =(($H$2-($H$2*0.2))/3)*CONTROL!$R14 -> 533.33333 | T14: =((CONTROL!$R14*$H$2)*26.66666%)+IF(V14="SI",$M$2/$V$2,0) -> 1333.2832 | U14: =SUMIFS(E$56:Q$56,E14:Q14,"X")+IF(V14="SI",$M$2,0) -> 35198.995 | V14: SI
A15: =A14+1 -> 12 | B15: COD 12 | R15: =COUNTIF(E15:Q15,"X") -> 0 | S15: =(($H$2-($H$2*0.2))/3)*CONTROL!$R15 -> 0 | T15: =((CONTROL!$R15*$H$2)*26.66666%)+IF(V15="SI",$M$2/$V$2,0) -> 0 | U15: =SUMIFS(E$56:Q$56,E15:Q15,"X")+IF(V15="SI",$M$2,0) -> 0 | V15: NO
A16: =A15+1 -> 13 | B16: COD 13 | C16: NOTAS HIPICAS | D16: 0 | E16: 0 | F16: 0 | G16: 0 | R16: =COUNTIF(E16:Q16,"X") -> 0 | S16: =(($H$2-($H$2*0.2))/3)*CONTROL!$R16 -> 0 | T16: =((CONTROL!$R16*$H$2)*26.66666%)+IF(V16="SI",$M$2/$V$2,0) -> 0 | U16: =SUMIFS(E$56:Q$56,E16:Q16,"X")+IF(V16="SI",$M$2,0) -> 0 | V16: NO
A17: =A16+1 -> 14 | B17: COD 14 | C17: PEDRO ALVAREZ | D17: 3000 | E17: X | F17: X | R17: =COUNTIF(E17:Q17,"X") -> 2 | S17: =(($H$2-($H$2*0.2))/3)*CONTROL!$R17 -> 533.33333 | T17: =((CONTROL!$R17*$H$2)*26.66666%)+IF(V17="SI",$M$2/$V$2,0) -> 1333.2832 | U17: =SUMIFS(E$56:Q$56,E17:Q17,"X")+IF(V17="SI",$M$2,0) -> 35198.995 | V17: SI
A18: =A17+1 -> 15 | B18: COD 15 | C18: CARLOS SUAREZ | D18: 3000 | E18: X | F18: X | R18: =COUNTIF(E18:Q18,"X") -> 2 | S18: =(($H$2-($H$2*0.2))/3)*CONTROL!$R18 -> 533.33333 | T18: =((CONTROL!$R18*$H$2)*26.66666%)+IF(V18="SI",$M$2/$V$2,0) -> 1333.2832 | U18: =SUMIFS(E$56:Q$56,E18:Q18,"X")+IF(V18="SI",$M$2,0) -> 35198.995 | V18: SI
A19: =A18+1 -> 16 | B19: COD 16 | C19: PODER HIPICO | D19: 3000 | E19: X | F19: X | R19: =COUNTIF(E19:Q19,"X") -> 2 | S19: =(($H$2-($H$2*0.2))/3)*CONTROL!$R19 -> 533.33333 | T19: =((CONTROL!$R19*$H$2)*26.66666%)+IF(V19="SI",$M$2/$V$2,0) -> 1333.2832 | U19: =SUMIFS(E$56:Q$56,E19:Q19,"X")+IF(V19="SI",$M$2,0) -> 35198.995 | V19: SI
A20: =A19+1 -> 17 | B20: COD 17 | C20: FERNANDO VALDIRIO | D20: 3000 | E20: X | F20: X | R20: =COUNTIF(E20:Q20,"X") -> 2 | S20: =(($H$2-($H$2*0.2))/3)*CONTROL!$R20 -> 533.33333 | T20: =((CONTROL!$R20*$H$2)*26.66666%)+IF(V20="SI",$M$2/$V$2,0) -> 1333.2832 | U20: =SUMIFS(E$56:Q$56,E20:Q20,"X")+IF(V20="SI",$M$2,0) -> 35198.995 | V20: SI
A21: =A20+1 -> 18 | B21: COD 18 | C21: CASTOR CHIRINOS | D21: 3000 | E21: - | F21: - | R21: =COUNTIF(E21:Q21,"X") -> 0 | S21: =(($H$2-($H$2*0.2))/3)*CONTROL!$R21 -> 0 | T21: =((CONTROL!$R21*$H$2)*26.66666%)+IF(V21="SI",$M$2/$V$2,0) -> 0 | U21: =SUMIFS(E$56:Q$56,E21:Q21,"X")+IF(V21="SI",$M$2,0) -> 0 | V21: NO
A22: =A21+1 -> 19 | B22: COD 19 | C22: EL SAMURAI HIPICO | D22: 3000 | E22: X | F22: X | G22: X | H22: O | I22: O | J22: O | K22: O | L22: O | R22: =COUNTIF(E22:Q22,"X") -> 3 | S22: =(($H$2-($H$2*0.2))/3)*CONTROL!$R22 -> 800 | T22: =((CONTROL!$R22*$H$2)*26.66666%)+IF(V22="SI",$M$2/$V$2,0) -> 1599.9498 | U22: =SUMIFS(E$56:Q$56,E22:Q22,"X")+IF(V22="SI",$M$2,0) -> 38665.661 | V22: SI
A23: =A22+1 -> 20 | B23: COD 20 | C23: CHINO | D23: 3000 | E23: X | F23: X | R23: =COUNTIF(E23:Q23,"X") -> 2 | S23: =(($H$2-($H$2*0.2))/3)*CONTROL!$R23 -> 533.33333 | T23: =((CONTROL!$R23*$H$2)*26.66666%)+IF(V23="SI",$M$2/$V$2,0) -> 1333.2832 | U23: =SUMIFS(E$56:Q$56,E23:Q23,"X")+IF(V23="SI",$M$2,0) -> 35198.995 | V23: SI
A24: =A23+1 -> 21 | B24: COD 21 | C24: WILMER | D24: 3000 | E24: X | F24: X | R24: =COUNTIF(E24:Q24,"X") -> 2 | S24: =(($H$2-($H$2*0.2))/3)*CONTROL!$R24 -> 533.33333 | T24: =((CONTROL!$R24*$H$2)*26.66666%)+IF(V24="SI",$M$2/$V$2,0) -> 533.3332 | U24: =SUMIFS(E$56:Q$56,E24:Q24,"X")+IF(V24="SI",$M$2,0) -> 19199.995 | V24: NO
A25: =A24+1 -> 22 | B25: COD 22 | C25: ROGER PIÑA | D25: 3000 | E25: X | F25: X | R25: =COUNTIF(E25:Q25,"X") -> 2 | S25: =(($H$2-($H$2*0.2))/3)*CONTROL!$R25 -> 533.33333 | T25: =((CONTROL!$R25*$H$2)*26.66666%)+IF(V25="SI",$M$2/$V$2,0) -> 533.3332 | U25: =SUMIFS(E$56:Q$56,E25:Q25,"X")+IF(V25="SI",$M$2,0) -> 19199.995 | V25: NO
A26: =A25+1 -> 23 | B26: COD 23 | C26: GILBERT | D26: 3000 | E26: X | F26: X | R26: =COUNTIF(E26:Q26,"X") -> 2 | S26: =(($H$2-($H$2*0.2))/3)*CONTROL!$R26 -> 533.33333 | T26: =((CONTROL!$R26*$H$2)*26.66666%)+IF(V26="SI",$M$2/$V$2,0) -> 533.3332 | U26: =SUMIFS(E$56:Q$56,E26:Q26,"X")+IF(V26="SI",$M$2,0) -> 19199.995 | V26: NO
A27: =A26+1 -> 24 | B27: COD 24 | R27: =COUNTIF(E27:Q27,"X") -> 0 | S27: =(($H$2-($H$2*0.2))/3)*CONTROL!$R27 -> 0 | T27: =((CONTROL!$R27*$H$2)*26.66666%)+IF(V27="SI",$M$2/$V$2,0) -> 0 | U27: =SUMIFS(E$56:Q$56,E27:Q27,"X")+IF(V27="SI",$M$2,0) -> 0 | V27: NO
A28: =A27+1 -> 25 | B28: COD 25 | C28: GLEY GARCIA | D28: 3000 | F28: X | R28: =COUNTIF(E28:Q28,"X") -> 1 | S28: =(($H$2-($H$2*0.2))/3)*CONTROL!$R28 -> 266.66667 | T28: =((CONTROL!$R28*$H$2)*26.66666%)+IF(V28="SI",$M$2/$V$2,0) -> 266.6666 | U28: =SUMIFS(E$56:Q$56,E28:Q28,"X")+IF(V28="SI",$M$2,0) -> 9599.9976 | V28: NO
A29: =A28+1 -> 26 | B29: COD 26 | C29: PEDRO TABEROA | D29: 3000 | E29: X | F29: X | R29: =COUNTIF(E29:Q29,"X") -> 2 | S29: =(($H$2-($H$2*0.2))/3)*CONTROL!$R29 -> 533.33333 | T29: =((CONTROL!$R29*$H$2)*26.66666%)+IF(V29="SI",$M$2/$V$2,0) -> 1333.2832 | U29: =SUMIFS(E$56:Q$56,E29:Q29,"X")+IF(V29="SI",$M$2,0) -> 35198.995 | V29: SI
A30: =A29+1 -> 27 | B30: COD 27 | C30: ANDERSON HERNANDEZ | D30: 3000 | E30: X | F30: X | R30: =COUNTIF(E30:Q30,"X") -> 2 | S30: =(($H$2-($H$2*0.2))/3)*CONTROL!$R30 -> 533.33333 | T30: =((CONTROL!$R30*$H$2)*26.66666%)+IF(V30="SI",$M$2/$V$2,0) -> 533.3332 | U30: =SUMIFS(E$56:Q$56,E30:Q30,"X")+IF(V30="SI",$M$2,0) -> 19199.995 | V30: NO
A31: =A30+1 -> 28 | B31: COD 28 | C31: FRANKLIN DELGADO | D31: 3000 | E31: X | F31: X | R31: =COUNTIF(E31:Q31,"X") -> 2 | S31: =(($H$2-($H$2*0.2))/3)*CONTROL!$R31 -> 533.33333 | T31: =((CONTROL!$R31*$H$2)*26.66666%)+IF(V31="SI",$M$2/$V$2,0) -> 533.3332 | U31: =SUMIFS(E$56:Q$56,E31:Q31,"X")+IF(V31="SI",$M$2,0) -> 19199.995 | V31: NO
A32: =A31+1 -> 29 | B32: COD 29 | C32: JEAN MARCO | D32: 3000 | E32: X | G32: X | R32: =COUNTIF(E32:Q32,"X") -> 2 | S32: =(($H$2-($H$2*0.2))/3)*CONTROL!$R32 -> 533.33333 | T32: =((CONTROL!$R32*$H$2)*26.66666%)+IF(V32="SI",$M$2/$V$2,0) -> 533.3332 | U32: =SUMIFS(E$56:Q$56,E32:Q32,"X")+IF(V32="SI",$M$2,0) -> 13066.663 | V32: NO
A33: =A32+1 -> 30 | B33: COD 30 | C33: CARIACO | D33: 3000 | E33: X | F33: X | R33: =COUNTIF(E33:Q33,"X") -> 2 | S33: =(($H$2-($H$2*0.2))/3)*CONTROL!$R33 -> 533.33333 | T33: =((CONTROL!$R33*$H$2)*26.66666%)+IF(V33="SI",$M$2/$V$2,0) -> 533.3332 | U33: =SUMIFS(E$56:Q$56,E33:Q33,"X")+IF(V33="SI",$M$2,0) -> 19199.995 | V33: NO
A34: =A33+1 -> 31 | B34: COD 31 | C34: ALBIN | D34: 3000 | E34: X | F34: X | R34: =COUNTIF(E34:Q34,"X") -> 2 | S34: =(($H$2-($H$2*0.2))/3)*CONTROL!$R34 -> 533.33333 | T34: =((CONTROL!$R34*$H$2)*26.66666%)+IF(V34="SI",$M$2/$V$2,0) -> 1333.2832 | U34: =SUMIFS(E$56:Q$56,E34:Q34,"X")+IF(V34="SI",$M$2,0) -> 35198.995 | V34: SI
A35: =A34+1 -> 32 | B35: COD 32 | C35: TONY CURTIS | D35: 3000 | E35: X | F35: X | G35: X | R35: =COUNTIF(E35:Q35,"X") -> 3 | S35: =(($H$2-($H$2*0.2))/3)*CONTROL!$R35 -> 800 | T35: =((CONTROL!$R35*$H$2)*26.66666%)+IF(V35="SI",$M$2/$V$2,0) -> 799.9998 | U35: =SUMIFS(E$56:Q$56,E35:Q35,"X")+IF(V35="SI",$M$2,0) -> 22666.661 | V35: NO
A36: =A35+1 -> 33 | B36: COD 33 | C36: JOSE LUIS ANTUNEZ | D36: 3000 | E36: X | F36: X | G36: X | R36: =COUNTIF(E36:Q36,"X") -> 3 | S36: =(($H$2-($H$2*0.2))/3)*CONTROL!$R36 -> 800 | T36: =((CONTROL!$R36*$H$2)*26.66666%)+IF(V36="SI",$M$2/$V$2,0) -> 799.9998 | U36: =SUMIFS(E$56:Q$56,E36:Q36,"X")+IF(V36="SI",$M$2,0) -> 22666.661 | V36: NO
A37: =A36+1 -> 34 | B37: COD 34 | C37: ROBERTO CARLOS | D37: 3000 | E37: X | F37: X | R37: =COUNTIF(E37:Q37,"X") -> 2 | S37: =(($H$2-($H$2*0.2))/3)*CONTROL!$R37 -> 533.33333 | T37: =((CONTROL!$R37*$H$2)*26.66666%)+IF(V37="SI",$M$2/$V$2,0) -> 533.3332 | U37: =SUMIFS(E$56:Q$56,E37:Q37,"X")+IF(V37="SI",$M$2,0) -> 19199.995 | V37: NO
A38: =A37+1 -> 35 | B38: COD 35 | C38: YOVANNY | D38: 3000 | E38: X | F38: X | G38: X | R38: =COUNTIF(E38:Q38,"X") -> 3 | S38: =(($H$2-($H$2*0.2))/3)*CONTROL!$R38 -> 800 | T38: =((CONTROL!$R38*$H$2)*26.66666%)+IF(V38="SI",$M$2/$V$2,0) -> 799.9998 | U38: =SUMIFS(E$56:Q$56,E38:Q38,"X")+IF(V38="SI",$M$2,0) -> 22666.661 | V38: NO
A39: =A38+1 -> 36 | B39: COD 36 | C39: EDGAR ALEXANDER | D39: 3000 | E39: X | F39: X | G39: X | R39: =COUNTIF(E39:Q39,"X") -> 3 | S39: =(($H$2-($H$2*0.2))/3)*CONTROL!$R39 -> 800 | T39: =((CONTROL!$R39*$H$2)*26.66666%)+IF(V39="SI",$M$2/$V$2,0) -> 799.9998 | U39: =SUMIFS(E$56:Q$56,E39:Q39,"X")+IF(V39="SI",$M$2,0) -> 22666.661 | V39: NO
A40: =A39+1 -> 37 | B40: COD 37 | C40: GLADIADOR HIPICO | D40: 0 | E40: X | F40: X | R40: =COUNTIF(E40:Q40,"X") -> 2 | S40: =(($H$2-($H$2*0.2))/3)*CONTROL!$R40 -> 533.33333 | T40: =((CONTROL!$R40*$H$2)*26.66666%)+IF(V40="SI",$M$2/$V$2,0) -> 533.3332 | U40: =SUMIFS(E$56:Q$56,E40:Q40,"X")+IF(V40="SI",$M$2,0) -> 19199.995 | V40: NO
A41: =A40+1 -> 38 | B41: COD 38 | C41: DERVIN | D41: 3000 | E41: X | F41: X | R41: =COUNTIF(E41:Q41,"X") -> 2 | S41: =(($H$2-($H$2*0.2))/3)*CONTROL!$R41 -> 533.33333 | T41: =((CONTROL!$R41*$H$2)*26.66666%)+IF(V41="SI",$M$2/$V$2,0) -> 533.3332 | U41: =SUMIFS(E$56:Q$56,E41:Q41,"X")+IF(V41="SI",$M$2,0) -> 19199.995 | V41: NO
...

Sheet SEM 1
B1: 0 | CV1: PREMIO | CX1: PREMIO | DA1: PREMIO
B2: CAMPEONATO DE MARCAS LA RINCONADA | CX2: MEETING | DA2: MEETING
B3: FECHA | D3: =CODIGOS_Y_PAGOS[[#Headers],[06/09/2026]] -> 06/09/2026 | F3: PARTICIPACION | O3: =CONTROL!H2 -> 1000 | T3: COMBINACIONES | AC3: =COUNTA(BASE01[COD])-COUNTIF(BASE01[TIPO],"NO ENVIÓ") -> 39 | AH3: PAGADAS | AN3: =COUNTIF(BASE01[TIPO],"PREMIO") -> 36 | AS3: RECAUDADO | AY3: =+O3*AN3 -> 36000 | CG3: SEMANA 1 | CX3: NO ENVIÓ
B4: =COUNTA(F6,K6,P6,U6,Z6,AE6,AJ6,AO6,AT6,AY6,BD6,BI6,BN6,BS6,BX6,CC6) -> 13 | C4: PRUEBAS | D4: ORDEN DE LLEGADA | E4: =D5+1 -> 1 | J4: =E4+1 -> 2 | O4: =J4+1 -> 3 | T4: =O4+1 -> 4 | Y4: =T4+1 -> 5 | AD4: =Y4+1 -> 6 | AI4: =AD4+1 -> 7 | AN4: =AI4+1 -> 8 | AS4: =AN4+1 -> 9 | AX4: =AS4+1 -> 10 | BC4: =AX4+1 -> 11 | BH4: =BC4+1 -> 12 | BM4: =BH4+1 -> 13 | BR4: =BM4+1 -> 14 | BW4: =BR4+1 -> 15 | CB4: =BW4+1 -> 16 | CG4: PORCENTAJE DE ACIERTOS | CX4: PENDIENTE
B5: =ROUNDUP($C$5/2, 0) -> 7 | C5: =COUNTA('SEM 1'!E8,'SEM 1'!J8,'SEM 1'!O8,'SEM 1'!T8,'SEM 1'!Y8,'SEM 1'!AD8,'SEM 1'!AI8,'SEM 1'!AN8,'SEM 1'!AS8,'SEM 1'!AX8,'SEM 1'!BC8,'SEM 1'!BH8,'SEM 1'!BM8,'SEM 1'!BR8,'SEM 1'!BW8,'SEM 1'!CB8) -> 13 | D5: 0 | E5: 8 | F5: 6 | G5: 4 | H5: =E5&"SF" -> 8SF | I5: =E5&"F" -> 8F | J5: 3 | K5: 8 | L5: 5 | M5: =J5&"SF" -> 3SF | N5: =J5&"F" -> 3F | O5: 6 | P5: 8 | Q5: 5 | R5: =O5&"SF" -> 6SF | S5: =O5&"F" -> 6F | T5: 6 | U5: 9 | V5: 7 | W5: =T5&"SF" -> 6SF | X5: =T5&"F" -> 6F | Y5: 5 | Z5: 8 | AA5: 6 | AB5: =Y5&"SF" -> 5SF | AC5: =Y5&"F" -> 5F | AD5: 2 | AE5: 5 | AF5: 7 | AG5: =AD5&"SF" -> 2SF | AH5: =AD5&"F" -> 2F | AI5: 4 | AJ5: 3 | AK5: 6 | AL5: =AI5&"SF" -> 4SF | AM5: =AI5&"F" -> 4F | AN5: 5 | AO5: 6 | AP5: 4 | AQ5: =AN5&"SF" -> 5SF | AR5: =AN5&"F" -> 5F | AS5: 4 | AT5: 1 | AU5: 7 | AV5: =AS5&"SF" -> 4SF | AW5: =AS5&"F" -> 4F | AX5: 1 | AY5: 2 | AZ5: 7 | BA5: =AX5&"SF" -> 1SF | BB5: =AX5&"F" -> 1F | BC5: 4 | BD5: 2 | BE5: 7 | BF5: =BC5&"SF" -> 4SF | BG5: =BC5&"F" -> 4F | BH5: 2 | BI5: 6 | BJ5: 5 | BK5: =BH5&"SF" -> 2SF | BL5: =$BH$5&"F" -> 2F | BM5: 3 | BN5: 9 | BO5: 2 | BP5: =BM5&"SF" -> 3SF | BQ5: =BM5&"F" -> 3F | BR5: - | BU5: =BR5&"SF" -> -SF | BV5: =BR5&"F" -> -F | BW5: - | BZ5: =BW5&"SF" -> -SF | CA5: =BW5&"F" -> -F | CB5: - | CE5: =CB5&"SF" -> -SF | CF5: =CB5&"F" -> -F | CS5: PREMIO | CU5: =(AY3*80%)/3 -> 9600
B6: =COUNTA(F6,Z6,AY6) -> 3 | C6: FIJAS | E6: DIV | F6: 259.28 | J6: DIV | K6: 211.39 | O6: DIV | P6: 298.11 | T6: DIV | U6: 110 | Y6: DIV | Z6: 110 | AD6: DIV | AE6: 232.48 | AI6: DIV | AJ6: 183.74 | AN6: DIV | AO6: 802.92 | AS6: DIV | AT6: 3121.92 | AX6: DIV | AY6: 235.64 | BC6: DIV | BD6: 184.94 | BH6: DIV | BI6: 532.81 | BM6: DIV | BN6: 272.76 | BR6: DIV | BW6: DIV | CB6: DIV | CG6: UNA MARCA | CJ6: DOS MARCAS | CM6: TRES MARCAS | CP6: FIJAS | CS6: SEMANA | CT6: VIENEN | CU6: GENERAL | CV6: PAGO | DB6: ACIERTO DE FIJAS | DT6: ACIERTO DE SUPERFIJAS
B7: 0 | C7: COD | D7: TIPO | E7: 1 | F7: 2 | G7: 22 | H7: 3 | I7: PTS | J7: 12 | K7: Columna2 | L7: Columna23 | M7: Columna28 | N7: Columna3 | O7: Columna4 | P7: Columna5 | Q7: Columna53 | R7: Columna52 | S7: Columna6 | T7: Columna7 | U7: Columna8 | V7: Columna83 | W7: Columna82 | X7: Columna9 | Y7: Columna10 | Z7: Columna11 | AA7: Columna113 | AB7: Columna112 | AC7: Columna12 | AD7: 1RA | AE7: 2DA | AF7: 2DA2 | AG7: 3RA | AH7: Columna15 | AI7: Columna16 | AJ7: Columna17 | AK7: Columna173 | AL7: Columna172 | AM7: Columna18 | AN7: 123 | AO7: 555 | AP7: 556 | AQ7: 111 | AR7: Columna21 | AS7: AAAA | AT7: BBBB | AU7: Columna13 | AV7: CCCC | AW7: Columna24 | AX7: Columna25 | AY7: Columna26 | AZ7: Columna263 | BA7: Columna262 | BB7: Columna27 | BC7: Columna272 | BD7: Columna273 | BE7: Columna2732 | BF7: Columna274 | BG7: Columna275 | BH7: Columna276 | BI7: Columna277 | BJ7: Columna2772 | BK7: Columna278 | BL7: Columna279 | BM7: Columna280 | BN7: Columna281 | BO7: Columna2812 | BP7: Columna282 | BQ7: Columna283 | BR7: Columna2802 | BS7: Columna2813 | BT7: Columna28124 | BU7: Columna2825 | BV7: Columna28310 | BW7: Columna2803 | BX7: Columna2814 | BY7: Columna28125 | BZ7: Columna2826 | CA7: Columna2837 | CB7: Columna2804 | CC7: Columna2815 | CD7: Columna28126 | CE7: Columna2827 | CF7: Columna2838 | CG7: Columna14 | CH7: Columna19 | CI7: Columna20 | CJ7: Columna29 | CK7: Columna30 | CL7: Columna31 | CM7: Columna32 | CN7: Columna34 | CO7: Columna35 | CP7: Columna36 | CQ7: Columna37 | CR7: Columna38 | CS7: Columna1 | CT7: Columna22 | CU7: Columna33 | CV7: Columna44 | CY7: CARRERA | CZ7: DIVIDENDO | DB7: CODIGO | DC7: 1 | DD7: 2 | DE7: 3 | DF7: 4 | DG7: 5 | DH7: 6 | DI7: 7 | DJ7: 8 | DK7: 9 | DL7: 10 | DM7: 11 | DN7: 12 | DO7: 13 | DP7: 14 | DQ7: 15 | DR7: 16 | DT7: CODIGO | DU7: 1 | DV7: 2 | DW7: 3 | DX7: 4 | DY7: 5 | DZ7: 6 | EA7: 7 | EB7: 8 | EC7: 9 | ED7: 10 | EE7: 11 | EF7: 12 | EG7: 13 | EH7: 14 | EI7: 15 | EJ7: 16
B8: =IF(BASE01[[#This Row],[COD]]<>"",B7+1,"") -> 1 | C8: COD 01 | D8: {=IF(BASE01[[#This Row],[COD]]="","",_xlfn.IFS(_xlfn.XLOOKUP(BASE01[[#This Row],[COD]],CODIGOS_Y_PAGOS[CODIGO],CODIGOS_Y_PAGOS[06/09/2026],"")="X","PREMIO",_xlfn.XLOOKUP(BASE01[[#This Row],[COD]],CODIGOS_Y_PAGOS[CODIGO],CODIGOS_Y_PAGOS[06/09/2026],"")="","NO ENVIÓ",_xlfn.XLOOKUP(BASE01[[#This Row],[COD]],CODIGOS_Y_PAGOS[CODIGO],CODIGOS_Y_PAGOS[06/09/2026],"")=0,"MEETING",_xlfn.XLOOKUP(BASE01[[#This Row],[COD]],CODIGOS_Y_PAGOS[CODIGO],CODIGOS_Y_PAGOS[06/09/2026],"")="O","PREMIO",_xlfn.XLOOKUP(BASE01[[#This Row],[COD]],CODIGOS_Y_PAGOS[CODIGO],CODIGOS_Y_PAGOS[06/09/2026],"")="-","PAGO PENDIENTE"))} -> PREMIO | E8: 6 | F8: 1 | G8: 8 | I8: =SUM(IF(E8=E$5,4,0),IF(E8&F8=E$5&F$5,1,0), IF(AND(E8=E$5,F$6>=$D$115),1,0), IF(AND(F8=E$5,F$6>=$D$115),1,0), IF(AND(G8=E$5,F$6>=$D$115),1,0), IF(E8&H8=I$5,1,0), IF(F8=E$5,2,0), IF(G8=E$5,1,0), IF(OR(E8&F8&G8=E$5&F$5&G$5,E8&F8&G8=E$5&G$5&F$5,E8&F8&G8=F$5&E$5&G$5,E8&F8&G8=F$5&G$5&E$5,E8&F8&G8=G$5&E$5&F$5,E8&F8&G8=G$5&F$5&E$5),2,0),IF(AND(E8=E$5,F$6>=$D$129),1,0),IF(AND(F8=E$5,F$6>=$D$129),1,0),IF(AND(G8=E$5,F$6>=$D$129),1,0),IF(E8&H8=H$5,4,0),IF(AND(E8=E$5,F$6<=$D$104),-0.5,0),IF(AND(F8=E$5,F$6<=$D$104),-0.5,0),IF(AND(G8=E$5,F$6<=$D$104),-0.5,0)) -> 1 | J8: 8 | K8: 3 | L8: 5 | N8: =SUM(IF(J8=J$5,4,0),IF(J8&K8=J$5&K$5,1,0), IF(AND(J8=J$5,K$6>=$D$115),1,0), IF(AND(K8=J$5,K$6>=$D$115),1,0), IF(AND(L8=J$5,K$6>=$D$115),1,0), IF(J8&M8=N$5,1,0), IF(K8=J$5,2,0), IF(L8=J$5,1,0), IF(OR(J8&K8&L8=J$5&K$5&L$5,J8&K8&L8=J$5&L$5&K$5,J8&K8&L8=K$5&J$5&L$5,J8&K8&L8=K$5&L$5&J$5,J8&K8&L8=L$5&J$5&K$5,J8&K8&L8=L$5&K$5&J$5),2,0),IF(AND(J8=J$5,K$6>=$D$129),1,0),IF(AND(K8=J$5,K$6>=$D$129),1,0),IF(AND(L8=J$5,K$6>=$D$129),1,0),IF(J8&M8=M$5,4,0),IF(AND(J8=J$5,K$6<=$D$104),-0.5,0),IF(AND(K8=J$5,K$6<=$D$104),-0.5,0),IF(AND(L8=J$5,K$6<=$D$104),-0.5,0)) -> 4 | O8: 2 | P8: 1 | Q8: 6 | S8: =SUM(IF(O8=O$5,4,0),IF(O8&P8=O$5&P$5,1,0), IF(AND(O8=O$5,P$6>=$D$115),1,0), IF(AND(P8=O$5,P$6>=$D$115),1,0), IF(AND(Q8=O$5,P$6>=$D$115),1,0), IF(O8&R8=S$5,1,0), IF(P8=O$5,2,0), IF(Q8=O$5,1,0), IF(OR(O8&P8&Q8=O$5&P$5&Q$5,O8&P8&Q8=O$5&Q$5&P$5,O8&P8&Q8=P$5&O$5&Q$5,O8&P8&Q8=P$5&Q$5&O$5,O8&P8&Q8=Q$5&O$5&P$5,O8&P8&Q8=Q$5&P$5&O$5),2,0),IF(AND(O8=O$5,P$6>=$D$129),1,0),IF(AND(P8=O$5,P$6>=$D$129),1,0),IF(AND(Q8=O$5,P$6>=$D$129),1,0),IF(O8&R8=R$5,4,0),IF(AND(O8=O$5,P$6<=$D$104),-0.5,0),IF(AND(P8=O$5,P$6<=$D$104),-0.5,0),IF(AND(Q8=O$5,P$6<=$D$104),-0.5,0)) -> 1 | T8: 6 | U8: 2 | V8: 8 | W8: F | X8: =SUM(IF(T8=T$5,4,0),IF(T8&U8=T$5&U$5,1,0), IF(AND(T8=T$5,U$6>=$D$115),1,0), IF(AND(U8=T$5,U$6>=$D$115),1,0), IF(AND(V8=T$5,U$6>=$D$115),1,0), IF(T8&W8=X$5,1,0), IF(U8=T$5,2,0), IF(V8=T$5,1,0), IF(OR(T8&U8&V8=T$5&U$5&V$5,T8&U8&V8=T$5&V$5&U$5,T8&U8&V8=U$5&T$5&V$5,T8&U8&V8=U$5&V$5&T$5,T8&U8&V8=V$5&T$5&U$5,T8&U8&V8=V$5&U$5&T$5),2,0),IF(AND(T8=T$5,U$6>=$D$129),1,0),IF(AND(U8=T$5,U$6>=$D$129),1,0),IF(AND(V8=T$5,U$6>=$D$129),1,0),IF(T8&W8=W$5,4,0),IF(AND(T8=T$5,U$6<=$D$104),-0.5,0),IF(AND(U8=T$5,U$6<=$D$104),-0.5,0),IF(AND(V8=T$5,U$6<=$D$104),-0.5,0)) -> 4.5 | Y8: 5 | Z8: 3 | AA8: 10 | AC8: =SUM(IF(Y8=Y$5,4,0),IF(Y8&Z8=Y$5&Z$5,1,0), IF(AND(Y8=Y$5,Z$6>=$D$115),1,0), IF(AND(Z8=Y$5,Z$6>=$D$115),1,0), IF(AND(AA8=Y$5,Z$6>=$D$115),1,0), IF(Y8&AB8=AC$5,1,0), IF(Z8=Y$5,2,0), IF(AA8=Y$5,1,0), IF(OR(Y8&Z8&AA8=Y$5&Z$5&AA$5,Y8&Z8&AA8=Y$5&AA$5&Z$5,Y8&Z8&AA8=Z$5&Y$5&AA$5,Y8&Z8&AA8=Z$5&AA$5&Y$5,Y8&Z8&AA8=AA$5&Y$5&Z$5,Y8&Z8&AA8=AA$5&Z$5&Y$5),2,0),IF(AND(Y8=Y$5,Z$6>=$D$129),1,0),IF(AND(Z8=Y$5,Z$6>=$D$129),1,0),IF(AND(AA8=Y$5,Z$6>=$D$129),1,0),IF(Y8&AB8=AB$5,4,0),IF(AND(Y8=Y$5,Z$6<=$D$104),-0.5,0),IF(AND(Z8=Y$5,Z$6<=$D$104),-0.5,0),IF(AND(AA8=Y$5,Z$6<=$D$104),-0.5,0)) -> 3.5 | AD8: 5 | AE8: 7 | AF8: 2 | AH8: =SUM(IF(AD8=AD$5,4,0),IF(AD8&AE8=AD$5&AE$5,1,0), IF(AND(AD8=AD$5,AE$6>=$D$115),1,0), IF(AND(AE8=AD$5,AE$6>=$D$115),1,0), IF(AND(AF8=AD$5,AE$6>=$D$115),1,0), IF(AD8&AG8=AH$5,1,0), IF(AE8=AD$5,2,0), IF(AF8=AD$5,1,0), IF(OR(AD8&AE8&AF8=AD$5&AE$5&AF$5,AD8&AE8&AF8=AD$5&AF$5&AE$5,AD8&AE8&AF8=AE$5&AD$5&AF$5,AD8&AE8&AF8=AE$5&AF$5&AD$5,AD8&AE8&AF8=AF$5&AD$5&AE$5,AD8&AE8&AF8=AF$5&AE$5&AD$5),2,0),IF(AND(AD8=AD$5,AE$6>=$D$129),1,0),IF(AND(AE8=AD$5,AE$6>=$D$129),1,0),IF(AND(AF8=AD$5,AE$6>=$D$129),1,0),IF(AD8&AG8=AG$5,4,0),IF(AND(AD8=AD$5,AE$6<=$D$104),-0.5,0),IF(AND(AE8=AD$5,AE$6<=$D$104),-0.5,0),IF(AND(AF8=AD$5,AE$6<=$D$104),-0.5,0)) -> 3 | AI8: 3 | AJ8: 1 | AK8: 4 | AM8: =SUM(IF(AI8=AI$5,4,0),IF(AI8&AJ8=AI$5&AJ$5,1,0), IF(AND(AI8=AI$5,AJ$6>=$D$115),1,0), IF(AND(AJ8=AI$5,AJ$6>=$D$115),1,0), IF(AND(AK8=AI$5,AJ$6>=$D$115),1,0), IF(AI8&AL8=AM$5,1,0), IF(AJ8=AI$5,2,0), IF(AK8=AI$5,1,0), IF(OR(AI8&AJ8&AK8=AI$5&AJ$5&AK$5,AI8&AJ8&AK8=AI$5&AK$5&AJ$5,AI8&AJ8&AK8=AJ$5&AI$5&AK$5,AI8&AJ8&AK8=AJ$5&AK$5&AI$5,AI8&AJ8&AK8=AK$5&AI$5&AJ$5,AI8&AJ8&AK8=AK$5&AJ$5&AI$5),2,0),IF(AND(AI8=AI$5,AJ$6>=$D$129),1,0),IF(AND(AJ8=AI$5,AJ$6>=$D$129),1,0),IF(AND(AK8=AI$5,AJ$6>=$D$129),1,0),IF(AI8&AL8=AL$5,4,0),IF(AND(AI8=AI$5,AJ$6<=$D$104),-0.5,0),IF(AND(AJ8=AI$5,AJ$6<=$D$104),-0.5,0),IF(AND(AK8=AI$5,AJ$6<=$D$104),-0.5,0)) -> 1 | AN8: 8 | AO8: 9 | AP8: 7 | AR8: =SUM(IF(AN8=AN$5,4,0),IF(AN8&AO8=AN$5&AO$5,1,0), IF(AND(AN8=AN$5,AO$6>=$D$115),1,0), IF(AND(AO8=AN$5,AO$6>=$D$115),1,0), IF(AND(AP8=AN$5,AO$6>=$D$115),1,0), IF(AN8&AQ8=AR$5,1,0), IF(AO8=AN$5,2,0), IF(AP8=AN$5,1,0), IF(OR(AN8&AO8&AP8=AN$5&AO$5&AP$5,AN8&AO8&AP8=AN$5&AP$5&AO$5,AN8&AO8&AP8=AO$5&AN$5&AP$5,AN8&AO8&AP8=AO$5&AP$5&AN$5,AN8&AO8&AP8=AP$5&AN$5&AO$5,AN8&AO8&AP8=AP$5&AO$5&AN$5),2,0),IF(AND(AN8=AN$5,AO$6>=$D$129),1,0),IF(AND(AO8=AN$5,AO$6>=$D$129),1,0),IF(AND(AP8=AN$5,AO$6>=$D$129),1,0),IF(AN8&AQ8=AQ$5,4,0),IF(AND(AN8=AN$5,AO$6<=$D$104),-0.5,0),IF(AND(AO8=AN$5,AO$6<=$D$104),-0.5,0),IF(AND(AP8=AN$5,AO$6<=$D$104),-0.5,0)) -> 0 | AS8: 1 | AV8: SF | AW8: =SUM(IF(AS8=AS$5,4,0),IF(AS8&AT8=AS$5&AT$5,1,0), IF(AND(AS8=AS$5,AT$6>=$D$115),1,0), IF(AND(AT8=AS$5,AT$6>=$D$115),1,0), IF(AND(AU8=AS$5,AT$6>=$D$115),1,0), IF(AS8&AV8=AW$5,1,0), IF(AT8=AS$5,2,0), IF(AU8=AS$5,1,0), IF(OR(AS8&AT8&AU8=AS$5&AT$5&AU$5,AS8&AT8&AU8=AS$5&AU$5&AT$5,AS8&AT8&AU8=AT$5&AS$5&AU$5,AS8&AT8&AU8=AT$5&AU$5&AS$5,AS8&AT8&AU8=AU$5&AS$5&AT$5,AS8&AT8&AU8=AU$5&AT$5&AS$5),2,0),IF(AND(AS8=AS$5,AT$6>=$D$129),1,0),IF(AND(AT8=AS$5,AT$6>=$D$129),1,0),IF(AND(AU8=AS$5,AT$6>=$D$129),1,0),IF(AS8&AV8=AV$5,4,0),IF(AND(AS8=AS$5,AT$6<=$D$104),-0.5,0),IF(AND(AT8=AS$5,AT$6<=$D$104),-0.5,0),IF(AND(AU8=AS$5,AT$6<=$D$104),-0.5,0)) -> 0 | AX8: 9 | AY8: 1 | AZ8: 8 | BB8: =SUM(IF(AX8=AX$5,4,0),IF(AX8&AY8=AX$5&AY$5,1,0), IF(AND(AX8=AX$5,AY$6>=$D$115),1,0), IF(AND(AY8=AX$5,AY$6>=$D$115),1,0), IF(AND(AZ8=AX$5,AY$6>=$D$115),1,0), IF(AX8&BA8=BB$5,1,0), IF(AY8=AX$5,2,0), IF(AZ8=AX$5,1,0), IF(OR(AX8&AY8&AZ8=AX$5&AY$5&AZ$5,AX8&AY8&AZ8=AX$5&AZ$5&AY$5,AX8&AY8&AZ8=AY$5&AX$5&AZ$5,AX8&AY8&AZ8=AY$5&AZ$5&AX$5,AX8&AY8&AZ8=AZ$5&AX$5&AY$5,AX8&AY8&AZ8=AZ$5&AY$5&AX$5),2,0),IF(AND(AX8=AX$5,AY$6>=$D$129),1,0),IF(AND(AY8=AX$5,AY$6>=$D$129),1,0),IF(AND(AZ8=AX$5,AY$6>=$D$129),1,0),IF(AX8&BA8=BA$5,4,0),IF(AND(AX8=AX$5,AY$6<=$D$104),-0.5,0),IF(AND(AY8=AX$5,AY$6<=$D$104),-0.5,0),IF(AND(AZ8=AX$5,AY$6<=$D$104),-0.5,0)) -> 2 | BC8: 4 | BD8: 6 | BE8: 2 | BG8: =SUM(IF(BC8=BC$5,4,0),IF(BC8&BD8=BC$5&BD$5,1,0), IF(AND(BC8=BC$5,BD$6>=$D$115),1,0), IF(AND(BD8=BC$5,BD$6>=$D$115),1,0), IF(AND(BE8=BC$5,BD$6>=$D$115),1,0), IF(BC8&BF8=BG$5,1,0), IF(BD8=BC$5,2,0), IF(BE8=BC$5,1,0), IF(OR(BC8&BD8&BE8=BC$5&BD$5&BE$5,BC8&BD8&BE8=BC$5&BE$5&BD$5,BC8&BD8&BE8=BD$5&BC$5&BE$5,BC8&BD8&BE8=BD$5&BE$5&BC$5,BC8&BD8&BE8=BE$5&BC$5&BD$5,BC8&BD8&BE8=BE$5&BD$5&BC$5),2,0),IF(AND(BC8=BC$5,BD$6>=$D$129),1,0),IF(AND(BD8=BC$5,BD$6>=$D$129),1,0),IF(AND(BE8=BC$5,BD$6>=$D$129),1,0),IF(BC8&BF8=BF$5,4,0),IF(AND(BC8=BC$5,BD$6<=$D$104),-0.5,0),IF(AND(BD8=BC$5,BD$6<=$D$104),-0.5,0),IF(AND(BE8=BC$5,BD$6<=$D$104),-0.5,0)) -> 4 | BH8: 5 | BI8: 1 | BJ8: 2 | BK8: F | BL8: =SUM(IF(BH8=BH$5,4,0),IF(BH8&BI8=BH$5&BI$5,1,0), IF(AND(BH8=BH$5,BI$6>=$D$115),1,0), IF(AND(BI8=BH$5,BI$6>=$D$115),1,0), IF(AND(BJ8=BH$5,BI$6>=$D$115),1,0), IF(BH8&BK8=BL$5,1,0), IF(BI8=BH$5,2,0), IF(BJ8=BH$5,1,0), IF(OR(BH8&BI8&BJ8=BH$5&BI$5&BJ$5,BH8&BI8&BJ8=BH$5&BJ$5&BI$5,BH8&BI8&BJ8=BI$5&BH$5&BJ$5,BH8&BI8&BJ8=BI$5&BJ$5&BH$5,BH8&BI8&BJ8=BJ$5&BH$5&BI$5,BH8&BI8&BJ8=BJ$5&BI$5&BH$5),2,0),IF(AND(BH8=BH$5,BI$6>=$D$129),1,0),IF(AND(BI8=BH$5,BI$6>=$D$129),1,0),IF(AND(BJ8=BH$5,BI$6>=$D$129),1,0),IF(BH8&BK8=BK$5,4,0),IF(AND(BH8=BH$5,BI$6<=$D$104),-0.5,0),IF(AND(BI8=BH$5,BI$6<=$D$104),-0.5,0),IF(AND(BJ8=BH$5,BI$6<=$D$104),-0.5,0)) -> 2 | BM8: 1 | BN8: 3 | BO8: 12 | BQ8: =SUM(IF(BM8=BM$5,4,0),IF(BM8&BN8=BM$5&BN$5,1,0), IF(AND(BM8=BM$5,BN$6>=$D$115),1,0), IF(AND(BN8=BM$5,BN$6>=$D$115),1,0), IF(AND(BO8=BM$5,BN$6>=$D$115),1,0), IF(BM8&BP8=BQ$5,1,0), IF(BN8=BM$5,2,0), IF(BO8=BM$5,1,0), IF(OR(BM8&BN8&BO8=BM$5&BN$5&BO$5,BM8&BN8&BO8=BM$5&BO$5&BN$5,BM8&BN8&BO8=BN$5&BM$5&BO$5,BM8&BN8&BO8=BN$5&BO$5&BM$5,BM8&BN8&BO8=BO$5&BM$5&BN$5,BM8&BN8&BO8=BO$5&BN$5&BM$5),2,0),IF(AND(BM8=BM$5,BN$6>=$D$129),1,0),IF(AND(BN8=BM$5,BN$6>=$D$129),1,0),IF(AND(BO8=BM$5,BN$6>=$D$129),1,0),IF(BM8&BP8=BP$5,4,0),IF(AND(BM8=BM$5,BN$6<=$D$104),-0.5,0),IF(AND(BN8=BM$5,BN$6<=$D$104),-0.5,0),IF(AND(BO8=BM$5,BN$6<=$D$104),-0.5,0)) -> 2 | BV8: =SUM(IF(BR8=BR$5,4,0),IF(BR8&BS8=BR$5&BS$5,1,0), IF(AND(BR8=BR$5,BS$6>=$D$115),1,0), IF(AND(BS8=BR$5,BS$6>=$D$115),1,0), IF(AND(BT8=BR$5,BS$6>=$D$115),1,0), IF(BR8&BU8=BV$5,1,0), IF(BS8=BR$5,2,0), IF(BT8=BR$5,1,0), IF(OR(BR8&BS8&BT8=BR$5&BS$5&BT$5,BR8&BS8&BT8=BR$5&BT$5&BS$5,BR8&BS8&BT8=BS$5&BR$5&BT$5,BR8&BS8&BT8=BS$5&BT$5&BR$5,BR8&BS8&BT8=BT$5&BR$5&BS$5,BR8&BS8&BT8=BT$5&BS$5&BR$5),2,0),IF(AND(BR8=BR$5,BS$6>=$D$129),1,0),IF(AND(BS8=BR$5,BS$6>=$D$129),1,0),IF(AND(BT8=BR$5,BS$6>=$D$129),1,0),IF(BR8&BU8=BU$5,4,0),IF(AND(BR8=BR$5,BS$6<=$D$104),-0.5,0),IF(AND(BS8=BR$5,BS$6<=$D$104),-0.5,0),IF(AND(BT8=BR$5,BS$6<=$D$104),-0.5,0)) -> 0 | CA8: =SUM(IF(BW8=BW$5,4,0),IF(BW8&BX8=BW$5&BX$5,1,0), IF(AND(BW8=BW$5,BX$6>=$D$115),1,0), IF(AND(BX8=BW$5,BX$6>=$D$115),1,0), IF(AND(BY8=BW$5,BX$6>=$D$115),1,0), IF(BW8&BZ8=CA$5,1,0), IF(BX8=BW$5,2,0), IF(BY8=BW$5,1,0), IF(OR(BW8&BX8&BY8=BW$5&BX$5&BY$5,BW8&BX8&BY8=BW$5&BY$5&BX$5,BW8&BX8&BY8=BX$5&BW$5&BY$5,BW8&BX8&BY8=BX$5&BY$5&BW$5,BW8&BX8&BY8=BY$5&BW$5&BX$5,BW8&BX8&BY8=BY$5&BX$5&BW$5),2,0),IF(AND(BW8=BW$5,BX$6>=$D$129),1,0),IF(AND(BX8=BW$5,BX$6>=$D$129),1,0),IF(AND(BY8=BW$5,BX$6>=$D$129),1,0),IF(BW8&BZ8=BZ$5,4,0),IF(AND(BW8=BW$5,BX$6<=$D$104),-0.5,0),IF(AND(BX8=BW$5,BX$6<=$D$104),-0.5,0),IF(AND(BY8=BW$5,BX$6<=$D$104),-0.5,0)) -> 0 | CF8: =SUM(IF(CB8=CB$5,4,0),IF(CB8&CC8=CB$5&CC$5,1,0), IF(AND(CB8=CB$5,CC$6>=$D$115),1,0), IF(AND(CC8=CB$5,CC$6>=$D$115),1,0), IF(AND(CD8=CB$5,CC$6>=$D$115),1,0), IF(CB8&CE8=CF$5,1,0), IF(CC8=CB$5,2,0), IF(CD8=CB$5,1,0), IF(OR(CB8&CC8&CD8=CB$5&CC$5&CD$5,CB8&CC8&CD8=CB$5&CD$5&CC$5,CB8&CC8&CD8=CC$5&CB$5&CD$5,CB8&CC8&CD8=CC$5&CD$5&CB$5,CB8&CC8&CD8=CD$5&CB$5&CC$5,CB8&CC8&CD8=CD$5&CC$5&CB$5),2,0),IF(AND(CB8=CB$5,CC$6>=$D$129),1,0),IF(AND(CC8=CB$5,CC$6>=$D$129),1,0),IF(AND(CD8=CB$5,CC$6>=$D$129),1,0),IF(CB8&CE8=CE$5,4,0),IF(AND(CB8=CB$5,CC$6<=$D$104),-0.5,0),IF(AND(CC8=CB$5,CC$6<=$D$104),-0.5,0),IF(AND(CD8=CB$5,CC$6<=$D$104),-0.5,0)) -> 0 | CG8: =IF(BASE01[[#This Row],[1]]="",0,$B$4) -> 13 | CH8: =COUNTIF(BASE01[[#This Row],[1]],$E$5)+COUNTIF(BASE01[[#This Row],[12]],$J$5)+COUNTIF(BASE01[[#This Row],[Columna4]],$O$5)+COUNTIF(BASE01[[#This Row],[Columna7]],$T$5)+COUNTIF(BASE01[[#This Row],[Columna10]],$Y$5)+COUNTIF(BASE01[[#This Row],[1RA]],$AD$5)+COUNTIF(BASE01[[#This Row],[Columna16]],$AI$5)+COUNTIF(BASE01[[#This Row],[123]],$AN$5)+COUNTIF(BASE01[[#This Row],[AAAA]],$AS$5)+COUNTIF(BASE01[[#This Row],[Columna25]],$AX$5)+COUNTIF(BASE01[[#This Row],[Columna272]],$BC$5)+COUNTIF(BASE01[[#This Row],[Columna276]],$BH$5)+COUNTIF(BASE01[[#This Row],[Columna280]],$BM$5)+COUNTIF(BASE01[[#This Row],[Columna2802]],$BR$5)+COUNTIF(BASE01[[#This Row],[Columna2803]],$BW$5)+COUNTIF(BASE01[[#This Row],[Columna2804]],$CB$5) -> 3 | CI8: =IF(BASE01[[#This Row],[Columna14]]=0,0,(CH8/CG8)) -> 0.23076923 | CJ8: =IF(BASE01[[#This Row],[1]]="",0,$B$4) -> 13 | CK8: =COUNTIF(BASE01[[#This Row],[1]]:BASE01[[#This Row],[2]],$E$5)+COUNTIF(BASE01[[#This Row],[12]]:BASE01[[#This Row],[Columna2]],$J$5)+COUNTIF(BASE01[[#This Row],[Columna4]]:BASE01[[#This Row],[Columna5]],$O$5)+COUNTIF(BASE01[[#This Row],[Columna7]]:BASE01[[#This Row],[Columna8]],$T$5)+COUNTIF(BASE01[[#This Row],[Columna10]]:BASE01[[#This Row],[Columna11]],$Y$5)+COUNTIF(BASE01[[#This Row],[1RA]]:BASE01[[#This Row],[2DA]],$AD$5)+COUNTIF(BASE01[[#This Row],[Columna16]:[Columna17]],$AI$5)+COUNTIF(BASE01[[#This Row],[123]:[555]],$AN$5)+COUNTIF(BASE01[[#This Row],[AAAA]]:BASE01[[#This Row],[BBBB]],$AS$5)+COUNTIF(BASE01[[#This Row],[Columna25]]:BASE01[[#This Row],[Columna26]],$AX$5)+COUNTIF(BASE01[[#This Row],[Columna272]]:BASE01[[#This Row],[Columna273]],$BC$5)+COUNTIF(BASE01[[#This Row],[Columna276]]:BASE01[[#This Row],[Columna277]],$BH$5)+COUNTIF(BASE01[[#This Row],[Columna280]]:BASE01[[#This Row],[Columna281]],$BM$5)+COUNTIF(BASE01[[#This Row],[Columna2802]]:BASE01[[#This Row],[Columna2813]],$BR$5)+COUNTIF(BASE01[[#This Row],[Columna2803]:[Columna2814]],$BW$5)+COUNTIF(BASE01[[#This Row],[Columna2804]:[Columna2815]],$CB$5) -> 6 | CL8: =IF(BASE01[[#This Row],[Columna14]]=0,0,(CK8/CJ8)) -> 0.46153846 | CM8: =IF(BASE01[[#This Row],[1]]="",0,$B$4) -> 13 | CN8: =COUNTIF(BASE01[[#This Row],[1]:[22]],$E$5)+COUNTIF(BASE01[[#This Row],[12]:[Columna23]],$J$5)+COUNTIF(BASE01[[#This Row],[Columna4]:[Columna53]],$O$5)+COUNTIF(BASE01[[#This Row],[Columna7]:[Columna83]],$T$5)+COUNTIF(BASE01[[#This Row],[Columna10]:[Columna113]],$Y$5)+COUNTIF(BASE01[[#This Row],[1RA]:[2DA2]],$AD$5)+COUNTIF(BASE01[[#This Row],[Columna16]:[Columna173]],$AI$5)+COUNTIF(BASE01[[#This Row],[123]:[556]],$AN$5)+COUNTIF(BASE01[[#This Row],[AAAA]:[Columna13]],$AS$5)+COUNTIF(BASE01[[#This Row],[Columna25]:[Columna263]],$AX$5)+COUNTIF(BASE01[[#This Row],[Columna272]:[Columna2732]],$BC$5)+COUNTIF(BASE01[[#This Row],[Columna276]:[Columna2772]],$BH$5)+COUNTIF(BASE01[[#This Row],[Columna280]:[Columna2812]],$BM$5)+COUNTIF(BASE01[[#This Row],[Columna2802]:[Columna28124]],$BR$5)+COUNTIF(BASE01[[#This Row],[Columna2803]:[Columna28125]],$BW$5)+COUNTIF(BASE01[[#This Row],[Columna2804]:[Columna28126]],$CB$5) -> 11 | CO8: =IF(BASE01[[#This Row],[Columna14]]=0,0,(CN8/CM8)) -> 0.84615385 | CP8: =SUM( (AND(OR(BASE01[[#This Row],[3]]="F", BASE01[[#This Row],[3]]="SF"), F$6<>"")), (AND(OR(BASE01[[#This Row],[Columna28]]="F", BASE01[[#This Row],[Columna28]]="SF"), K$6<>"")), (AND(OR(BASE01[[#This Row],[Columna52]]="F", BASE01[[#This Row],[Columna52]]="SF"), P$6<>"")), (AND(OR(BASE01[[#This Row],[Columna82]]="F", BASE01[[#This Row],[Columna82]]="SF"), U$6<>"")), (AND(OR(BASE01[[#This Row],[Columna112]]="F", BASE01[[#This Row],[Columna112]]="SF"), Z$6<>"")), (AND(OR(BASE01[[#This Row],[3RA]]="F", BASE01[[#This Row],[3RA]]="SF"), AE$6<>"")), (AND(OR(BASE01[[#This Row],[Columna172]]="F",BASE01[[#This Row],[Columna172]]="SF"), AJ$6<>"")), (AND(OR(BASE01[[#This Row],[111]]="F", BASE01[[#This Row],[111]]="SF"), AO$6<>"")), (AND(OR(BASE01[[#This Row],[CCCC]]="F", BASE01[[#This Row],[CCCC]]="SF"), AT$6<>"")), (AND(OR(BASE01[[#This Row],[Columna262]]="F",BASE01[[#This Row],[Columna262]]="SF"), AY$6<>"")), (AND(OR(BASE01[[#This Row],[Columna274]]="F", BASE01[[#This Row],[Columna274]]="SF"), BD$6<>"")), (AND(OR(BASE01[[#This Row],[Columna278]]="F", BASE01[[#This Row],[Columna278]]="SF"), BI$6<>"")), (AND(OR(BASE01[[#This Row],[Columna282]]="F", BASE01[[#This Row],[Columna282]]="SF"), BN$6<>"")), (AND(OR(BASE01[[#This Row],[Columna2825]]="F", BASE01[[#This Row],[Columna2825]]="SF"), BS$6<>"")), (AND(OR(BASE01[[#This Row],[Columna2826]]="F", BASE01[[#This Row],[Columna2826]]="SF"), BX$6<>"")), (AND(OR(BASE01[[#This Row],[Columna2827]]="F", BASE01[[#This Row],[Columna2827]]="SF"), CC$6<>"")) ) -> 3 | CQ8: =COUNTIFS(BASE01[[#This Row],[1]],$E$5,BASE01[[#This Row],[3]],"F")+COUNTIFS(BASE01[[#This Row],[12]],$J$5,BASE01[[#This Row],[Columna28]],"F")+COUNTIFS(BASE01[[#This Row],[Columna4]],$O$5,BASE01[[#This Row],[Columna52]],"F")+COUNTIFS(BASE01[[#This Row],[Columna7]],$T$5,BASE01[[#This Row],[Columna82]],"F")+COUNTIFS(BASE01[[#This Row],[Columna10]],$Y$5,BASE01[[#This Row],[Columna112]],"F")+COUNTIFS(BASE01[[#This Row],[1RA]],$AD$5,BASE01[[#This Row],[3RA]],"F")+COUNTIFS(BASE01[[#This Row],[Columna16]],$AI$5,BASE01[[#This Row],[Columna172]],"F")+COUNTIFS(BASE01[[#This Row],[123]],$AN$5,BASE01[[#This Row],[111]],"F")+COUNTIFS(BASE01[[#This Row],[AAAA]],$AS$5,BASE01[[#This Row],[CCCC]],"F")+COUNTIFS(BASE01[[#This Row],[Columna25]],$AX$5,BASE01[[#This Row],[Columna262]],"F")+COUNTIFS(BASE01[[#This Row],[Columna272]],$BC$5,BASE01[[#This Row],[Columna274]],"F")+COUNTIFS(BASE01[[#This Row],[Columna276]],$BH$5,BASE01[[#This Row],[Columna278]],"F")+COUNTIFS(BASE01[[#This Row],[Columna280]],$BM$5,BASE01[[#This Row],[Columna282]],"F")+COUNTIFS(BASE01[[#This Row],[1]],$E$5,BASE01[[#This Row],[3]],"SF")+COUNTIFS(BASE01[[#This Row],[12]],$J$5,BASE01[[#This Row],[Columna28]],"SF")+COUNTIFS(BASE01[[#This Row],[Columna4]],$O$5,BASE01[[#This Row],[Columna52]],"SF")+COUNTIFS(BASE01[[#This Row],[Columna7]],$T$5,BASE01[[#This Row],[Columna82]],"SF")+COUNTIFS(BASE01[[#This Row],[Columna10]],$Y$5,BASE01[[#This Row],[Columna112]],"SF")+COUNTIFS(BASE01[[#This Row],[1RA]],$AD$5,BASE01[[#This Row],[3RA]],"SF")+COUNTIFS(BASE01[[#This Row],[Columna16]],$AI$5,BASE01[[#This Row],[Columna172]],"SF")+COUNTIFS(BASE01[[#This Row],[123]],$AN$5,BASE01[[#This Row],[111]],"SF")+COUNTIFS(BASE01[[#This Row],[AAAA]],$AS$5,BASE01[[#This Row],[CCCC]],"SF")+COUNTIFS(BASE01[[#This Row],[Columna25]],$AX$5,BA8,"SF")+COUNTIFS(BASE01[[#This Row],[Columna272]],$BC$5,BASE01[[#This Row],[Columna274]],"SF")+COUNTIFS(BASE01[[#This Row],[Columna276]],$BH$5,BASE01[[#This Row],[Columna278]],"SF")+COUNTIFS(BASE01[[#This Row],[Columna280]],$BM$5,BASE01[[#This Row],[Columna282]],"SF") -> 1 | CR8: =IF(BASE01[[#This Row],[Columna14]]=0,0,(CQ8/CP8)) -> 0.33333333 | CS8: =SUM(BASE01[[#This Row],[PTS]],BASE01[[#This Row],[Columna3]],BASE01[[#This Row],[Columna6]],BASE01[[#This Row],[Columna9]],BASE01[[#This Row],[Columna12]],BASE01[[#This Row],[Columna15]],BASE01[[#This Row],[Columna18]],BASE01[[#This Row],[Columna21]],BASE01[[#This Row],[Columna24]],BASE01[[#This Row],[Columna27]],BASE01[[#This Row],[Columna275]],BASE01[[#This Row],[Columna279]],BASE01[[#This Row],[Columna283]],BASE01[[#This Row],[Columna28310]],BASE01[[#This Row],[Columna2837]],BASE01[[#This Row],[Columna2838]]) -> 28 | CU8: =SUM(CS8,CT8) -> 28 | CV8: =IF(BASE01[[#This Row],[TIPO]]="PREMIO",$O$3,"0,00") -> 1000 | CY8: 1 | CZ8: =F$6 -> 259.28 | DB8: =BASE01[[#This Row],[COD]] -> COD 01 | DC8: {=IFERROR(IF(AND(INDEX($E$8:$CE$57, MATCH($C8, $C$8:$C$57, 0), (COLUMNS($DC8:DC8)-1)*5 + 1) = INDEX($E$5:$CE$5, 1, (COLUMNS($DC8:DC8)-1)*5 + 1), INDEX($E$8:$CE$57, MATCH($C8, $C$8:$C$57, 0), (COLUMNS($DC8:DC8)-1)*5 + 4) = "F"), INDEX($CZ$8:$CZ$23, COLUMNS($DC8:DC8)), "0"), "")} -> 0 | DD8: {=IFERROR(IF(AND(INDEX($E$8:$CE$57, MATCH($C8, $C$8:$C$57, 0), (COLUMNS($DC8:DD8)-1)*5 + 1) = INDEX($E$5:$CE$5, 1, (COLUMNS($DC8:DD8)-1)*5 + 1), INDEX($E$8:$CE$57, MATCH($C8, $C$8:$C$57, 0), (COLUMNS($DC8:DD8)-1)*5 + 4) = "F"), INDEX($CZ$8:$CZ$23, COLUMNS($DC8:DD8)), "0"), "")} -> 0 | DE8: {=IFERROR(IF(AND(INDEX($E$8:$CE$57, MATCH($C8, $C$8:$C$57, 0), (COLUMNS($DC8:DE8)-1)*5 + 1) = INDEX($E$5:$CE$5, 1, (COLUMNS($DC8:DE8)-1)*5 + 1), INDEX($E$8:$CE$57, MATCH($C8, $C$8:$C$57, 0), (COLUMNS($DC8:DE8)-1)*5 + 4) = "F"), INDEX($CZ$8:$CZ$23, COLUMNS($DC8:DE8)), "0"), "")} -> 0 | DF8: {=IFERROR(IF(AND(INDEX($E$8:$CE$57, MATCH($C8, $C$8:$C$57, 0), (COLUMNS($DC8:DF8)-1)*5 + 1) = INDEX($E$5:$CE$5, 1, (COLUMNS($DC8:DF8)-1)*5 + 1), INDEX($E$8:$CE$57, MATCH($C8, $C$8:$C$57, 0), (COLUMNS($DC8:DF8)-1)*5 + 4) = "F"), INDEX($CZ$8:$CZ$23, COLUMNS($DC8:DF8)), "0"), "")} -> 110 | DG8: {=IFERROR(IF(AND(INDEX($E$8:$CE$57, MATCH($C8, $C$8:$C$57, 0), (COLUMNS($DC8:DG8)-1)*5 + 1) = INDEX($E$5:$CE$5, 1, (COLUMNS($DC8:DG8)-1)*5 + 1), INDEX($E$8:$CE$57, MATCH($C8, $C$8:$C$57, 0), (COLUMNS($DC8:DG8)-1)*5 + 4) = "F"), INDEX($CZ$8:$CZ$23, COLUMNS($DC8:DG8)), "0"), "")} -> 0 | DH8: {=IFERROR(IF(AND(INDEX($E$8:$CE$57, MATCH($C8, $C$8:$C$57, 0), (COLUMNS($DC8:DH8)-1)*5 + 1) = INDEX($E$5:$CE$5, 1, (COLUMNS($DC8:DH8)-1)*5 + 1), INDEX($E$8:$CE$57, MATCH($C8, $C$8:$C$57, 0), (COLUMNS($DC8:DH8)-1)*5 + 4) = "F"), INDEX($CZ$8:$CZ$23, COLUMNS($DC8:DH8)), "0"), "")} -> 0 | DI8: {=IFERROR(IF(AND(INDEX($E$8:$CE$57, MATCH($C8, $C$8:$C$57, 0), (COLUMNS($DC8:DI8)-1)*5 + 1) = INDEX($E$5:$CE$5, 1, (COLUMNS($DC8:DI8)-1)*5 + 1), INDEX($E$8:$CE$57, MATCH($C8, $C$8:$C$57, 0), (COLUMNS($DC8:DI8)-1)*5 + 4) = "F"), INDEX($CZ$8:$CZ$23, COLUMNS($DC8:DI8)), "0"), "")} -> 0 | DJ8: {=IFERROR(IF(AND(INDEX($E$8:$CE$57, MATCH($C8, $C$8:$C$57, 0), (COLUMNS($DC8:DJ8)-1)*5 + 1) = INDEX($E$5:$CE$5, 1, (COLUMNS($DC8:DJ8)-1)*5 + 1), INDEX($E$8:$CE$57, MATCH($C8, $C$8:$C$57, 0), (COLUMNS($DC8:DJ8)-1)*5 + 4) = "F"), INDEX($CZ$8:$CZ$23, COLUMNS($DC8:DJ8)), "0"), "")} -> 0 | ... DR8: {=IFERROR(IF(AND(INDEX($E$8:$CE$57, MATCH($C8, $C$8:$C$57, 0), (COLUMNS($DC8:DR8)-1)*5 + 1) = INDEX($E$5:$CE$5, 1, (COLUMNS($DC8:DR8)-1)*5 + 1), INDEX($E$8:$CE$57, MATCH($C8, $C$8:$C$57, 0), (COLUMNS($DC8:DR8)-1)*5 + 4) = "F"), INDEX($CZ$8:$CZ$23, COLUMNS($DC8:DR8)), "0"), "")} -> 0 | DT8: =BASE01[[#This Row],[COD]] -> COD 01 | DU8: {=IFERROR(IF(AND(INDEX($E$8:$CE$57, MATCH($C8, $C$8:$C$57, 0), (COLUMNS($DU8:DU8)-1)*5 + 1) = INDEX($E$5:$CE$5, 1, (COLUMNS($DU8:DU8)-1)*5 + 1), INDEX($E$8:$CE$57, MATCH($C8, $C$8:$C$57, 0), (COLUMNS($DU8:DU8)-1)*5 + 4) = "SF"), INDEX($CZ$8:$CZ$23, COLUMNS($DU8:DU8)), "0"), "")} -> 0 | DV8: {=IFERROR(IF(AND(INDEX($E$8:$CE$57, MATCH($C8, $C$8:$C$57, 0), (COLUMNS($DU8:DV8)-1)*5 + 1) = INDEX($E$5:$CE$5, 1, (COLUMNS($DU8:DV8)-1)*5 + 1), INDEX($E$8:$CE$57, MATCH($C8, $C$8:$C$57, 0), (COLUMNS($DU8:DV8)-1)*5 + 4) = "SF"), INDEX($CZ$8:$CZ$23, COLUMNS($DU8:DV8)), "0"), "")} -> 0 | DW8: {=IFERROR(IF(AND(INDEX($E$8:$CE$57, MATCH($C8, $C$8:$C$57, 0), (COLUMNS($DU8:DW8)-1)*5 + 1) = INDEX($E$5:$CE$5, 1, (COLUMNS($DU8:DW8)-1)*5 + 1), INDEX($E$8:$CE$57, MATCH($C8, $C$8:$C$57, 0), (COLUMNS($DU8:DW8)-1)*5 + 4) = "SF"), INDEX($CZ$8:$CZ$23, COLUMNS($DU8:DW8)), "0"), "")} -> 0 | DX8: {=IFERROR(IF(AND(INDEX($E$8:$CE$57, MATCH($C8, $C$8:$C$57, 0), (COLUMNS($DU8:DX8)-1)*5 + 1) = INDEX($E$5:$CE$5, 1, (COLUMNS($DU8:DX8)-1)*5 + 1), INDEX($E$8:$CE$57, MATCH($C8, $C$8:$C$57, 0), (COLUMNS($DU8:DX8)-1)*5 + 4) = "SF"), INDEX($CZ$8:$CZ$23, COLUMNS($DU8:DX8)), "0"), "")} -> 0 | DY8: {=IFERROR(IF(AND(INDEX($E$8:$CE$57, MATCH($C8, $C$8:$C$57, 0), (COLUMNS($DU8:DY8)-1)*5 + 1) = INDEX($E$5:$CE$5, 1, (COLUMNS($DU8:DY8)-1)*5 + 1), INDEX($E$8:$CE$57, MATCH($C8, $C$8:$C$57, 0), (COLUMNS($DU8:DY8)-1)*5 + 4) = "SF"), INDEX($CZ$8:$CZ$23, COLUMNS($DU8:DY8)), "0"), "")} -> 0 | DZ8: {=IFERROR(IF(AND(INDEX($E$8:$CE$57, MATCH($C8, $C$8:$C$57, 0), (COLUMNS($DU8:DZ8)-1)*5 + 1) = INDEX($E$5:$CE$5, 1, (COLUMNS($DU8:DZ8)-1)*5 + 1), INDEX($E$8:$CE$57, MATCH($C8, $C$8:$C$57, 0), (COLUMNS($DU8:DZ8)-1)*5 + 4) = "SF"), INDEX($CZ$8:$CZ$23, COLUMNS($DU8:DZ8)), "0"), "")} -> 0 | EA8: {=IFERROR(IF(AND(INDEX($E$8:$CE$57, MATCH($C8, $C$8:$C$57, 0), (COLUMNS($DU8:EA8)-1)*5 + 1) = INDEX($E$5:$CE$5, 1, (COLUMNS($DU8:EA8)-1)*5 + 1), INDEX($E$8:$CE$57, MATCH($C8, $C$8:$C$57, 0), (COLUMNS($DU8:EA8)-1)*5 + 4) = "SF"), INDEX($CZ$8:$CZ$23, COLUMNS($DU8:EA8)), "0"), "")} -> 0 | EB8: {=IFERROR(IF(AND(INDEX($E$8:$CE$57, MATCH($C8, $C$8:$C$57, 0), (COLUMNS($DU8:EB8)-1)*5 + 1) = INDEX($E$5:$CE$5, 1, (COLUMNS($DU8:EB8)-1)*5 + 1), INDEX($E$8:$CE$57, MATCH($C8, $C$8:$C$57, 0), (COLUMNS($DU8:EB8)-1)*5 + 4) = "SF"), INDEX($CZ$8:$CZ$23, COLUMNS($DU8:EB8)), "0"), "")} -> 0 | ... EJ8: {=IFERROR(IF(AND(INDEX($E$8:$CE$57, MATCH($C8, $C$8:$C$57, 0), (COLUMNS($DU8:EJ8)-1)*5 + 1) = INDEX($E$5:$CE$5, 1, (COLUMNS($DU8:EJ8)-1)*5 + 1), INDEX($E$8:$CE$57, MATCH($C8, $C$8:$C$57, 0), (COLUMNS($DU8:EJ8)-1)*5 + 4) = "SF"), INDEX($CZ$8:$CZ$23, COLUMNS($DU8:EJ8)), "0"), "")} -> 0
